Python 3.12.2 (tags/v3.12.2:6abddd9, Feb  6 2024, 21:26:36) [MSC v.1937 64 bit (AMD64)] on win32
Type "help", "copyright", "credits" or "license()" for more information.

= RESTART: D:\C Data 16-02-24\Desktop\Python_assignment_tops\Module 3\Check_Weather_and _exist_tuple.py
(1, 2, 3, 4, 11, 23, 'd', 'o', 'l', 'k', 'a', 'dholka')
Enter your element in the tuple : 
False

= RESTART: D:\C Data 16-02-24\Desktop\Python_assignment_tops\Module 3\Check_Weather_and _exist_tuple.py
(1, 2, 3, 4, 11, 23, 'd', 'o', 'l', 'k', 'a', 'dholka')
Enter your element in the tuple : 1
False

= RESTART: D:\C Data 16-02-24\Desktop\Python_assignment_tops\Module 3\Check_Weather_and _exist_tuple.py
(1, 2, 3, 4, 11, 23, 'd', 'o', 'l', 'k', 'a', 'dholka')
Enter your element in the tuple : dholka
True

= RESTART: D:\C Data 16-02-24\Desktop\Python_assignment_tops\Module 3\Check_Weather_and _exist_tuple.py
('d', 'o', 'l', 'k', 'a', 'dholka')
Enter your element in the tuple : s
False

= RESTART: D:\C Data 16-02-24\Desktop\Python_assignment_tops\Module 3\Replace_last_value_of_tuple_in_the_list.py
[(10, 20, 100), (40, 50, 100), (70, 80, 100)]

= RESTART: D:\C Data 16-02-24\Desktop\Python_assignment_tops\Module 3\Replace_last_value_of_tuple_in_the_list.py
[(10, 20, 100), (40, 50, 100), (70, 80, 100)]
[((10, 20, 30),), ((40, 50, 60),), ((70, 80, 90),)]

= RESTART: D:\C Data 16-02-24\Desktop\Python_assignment_tops\Module 3\Replace_last_value_of_tuple_in_the_list.py
[(10, 20, 100), (40, 50, 100), (70, 80, 100)]
<zip object at 0x000001A1564579C0>

= RESTART: D:\C Data 16-02-24\Desktop\Python_assignment_tops\Module 3\Replace_last_value_of_tuple_in_the_list.py
[(10, 20, 100), (40, 50, 100), (70, 80, 100)]
[<zip object at 0x000002817D5F7C00>]

= RESTART: D:\C Data 16-02-24\Desktop\Python_assignment_tops\Module 3\Replace_last_value_of_tuple_in_the_list.py
[(10, 20, 100), (40, 50, 100), (70, 80, 100)]
[<zip object at 0x000002180F6D7C00>]

= RESTART: D:\C Data 16-02-24\Desktop\Python_assignment_tops\Module 3\Replace_last_value_of_tuple_in_the_list.py
[(10, 20, 100), (40, 50, 100), (70, 80, 100)]
Traceback (most recent call last):
  File "D:\C Data 16-02-24\Desktop\Python_assignment_tops\Module 3\Replace_last_value_of_tuple_in_the_list.py", line 9, in <module>
    lst=[zip(last)]
NameError: name 'last' is not defined. Did you mean: 'lst'?

= RESTART: D:\C Data 16-02-24\Desktop\Python_assignment_tops\Module 3\Replace_last_value_of_tuple_in_the_list.py
[(10, 20, 100), (40, 50, 100), (70, 80, 100)]
[<zip object at 0x00000157F05A79C0>]

= RESTART: D:\C Data 16-02-24\Desktop\Python_assignment_tops\Module 3\Replace_last_value_of_tuple_in_the_list.py
[(10, 20, 100), (40, 50, 100), (70, 80, 100)]
[<zip object at 0x00000211147A7C00>]

= RESTART: D:\C Data 16-02-24\Desktop\Python_assignment_tops\Module 3\Replace_last_value_of_tuple_in_the_list.py
[(10, 20, 100), (40, 50, 100), (70, 80, 100)]
<zip object at 0x0000020DF61379C0>

= RESTART: D:\C Data 16-02-24\Desktop\Python_assignment_tops\Module 3\Replace_last_value_of_tuple_in_the_list.py
[(10, 20, 100), (40, 50, 100), (70, 80, 100)]
[<zip object at 0x000001D5958979C0>]

= RESTART: D:\C Data 16-02-24\Desktop\Python_assignment_tops\Module 3\Replace_last_value_of_tuple_in_the_list.py
[(10, 20, 100), (40, 50, 100), (70, 80, 100)]
Traceback (most recent call last):
  File "D:\C Data 16-02-24\Desktop\Python_assignment_tops\Module 3\Replace_last_value_of_tuple_in_the_list.py", line 11, in <module>
    print([(zip(last))])
NameError: name 'last' is not defined. Did you mean: 'lst'?

= RESTART: D:\C Data 16-02-24\Desktop\Python_assignment_tops\Module 3\Replace_last_value_of_tuple_in_the_list.py
[(10, 20, 100), (40, 50, 100), (70, 80, 100)]
[<zip object at 0x0000027DFAEB7CC0>]

= RESTART: D:\C Data 16-02-24\Desktop\Python_assignment_tops\Module 3\Replace_last_value_of_tuple_in_the_list.py
[(10, 20, 100), (40, 50, 100), (70, 80, 100)]
[<zip object at 0x000001AACE417CC0>]

= RESTART: D:/C Data 16-02-24/Desktop/Python_assignment_tops/Module 3/concatenate_Dictionary_and_create_new_dictionary.py
Traceback (most recent call last):
  File "D:/C Data 16-02-24/Desktop/Python_assignment_tops/Module 3/concatenate_Dictionary_and_create_new_dictionary.py", line 5, in <module>
    d3=({**d1}+{**d2})
TypeError: unsupported operand type(s) for +: 'dict' and 'dict'

= RESTART: D:/C Data 16-02-24/Desktop/Python_assignment_tops/Module 3/concatenate_Dictionary_and_create_new_dictionary.py
Traceback (most recent call last):
  File "D:/C Data 16-02-24/Desktop/Python_assignment_tops/Module 3/concatenate_Dictionary_and_create_new_dictionary.py", line 5, in <module>
    d3=Merge(d1+d2)
NameError: name 'Merge' is not defined

= RESTART: D:/C Data 16-02-24/Desktop/Python_assignment_tops/Module 3/concatenate_Dictionary_and_create_new_dictionary.py
{101: 'Tops', 102: 'Technologies', 103: 999, 104: 120, 'A': 122, 'B': 909, 'C': 'Ahmedabad', 'D': 7878}

= RESTART: D:/C Data 16-02-24/Desktop/Python_assignment_tops/Module 3/concatenate_Dictionary_and_create_new_dictionary.py
{101: 'Tops', 102: 'Technologies', 103: 999, 104: 120, 'A': 122, 'B': 909, 'C': 'Ahmedabad', 'D': 7878}

= RESTART: D:/C Data 16-02-24/Desktop/Python_assignment_tops/Module 3/Given_key_Exit_in_Dictionary.py
Enter key in the d :1
1
2
3
4
5
a
b
c

= RESTART: D:/C Data 16-02-24/Desktop/Python_assignment_tops/Module 3/Given_key_Exit_in_Dictionary.py
Enter key in the d :1
1
2
3
4
5
a
b
c

= RESTART: D:/C Data 16-02-24/Desktop/Python_assignment_tops/Module 3/Given_key_Exit_in_Dictionary.py
Enter key in the d :112
Key is not present 
Key is not present 
Key is not present 
Key is not present 
Key is not present 
Key is not present 
Key is not present 
Key is not present 

= RESTART: D:/C Data 16-02-24/Desktop/Python_assignment_tops/Module 3/Given_key_Exit_in_Dictionary.py
Enter key in the d :4
Key is not present 

= RESTART: D:/C Data 16-02-24/Desktop/Python_assignment_tops/Module 3/Given_key_Exit_in_Dictionary.py
Enter key in the d :5
NP

= RESTART: D:/C Data 16-02-24/Desktop/Python_assignment_tops/Module 3/Given_key_Exit_in_Dictionary.py
Enter key in the d :
= RESTART: D:/C Data 16-02-24/Desktop/Python_assignment_tops/Module 3/Given_key_Exit_in_Dictionary.py
Enter key in the d :a
P

= RESTART: D:/C Data 16-02-24/Desktop/Python_assignment_tops/Module 3/Given_key_Exit_in_Dictionary.py
Enter key in the d :yui
NP

= RESTART: D:/C Data 16-02-24/Desktop/Python_assignment_tops/Module 3/Given_key_Exit_in_Dictionary.py
Enter key in the d :ui
NP

= RESTART: D:/C Data 16-02-24/Desktop/Python_assignment_tops/Module 3/Given_key_Exit_in_Dictionary.py
Enter key in the d :1
NP

= RESTART: D:/C Data 16-02-24/Desktop/Python_assignment_tops/Module 3/Given_key_Exit_in_Dictionary.py
Enter key in the d :1
NP

= RESTART: D:/C Data 16-02-24/Desktop/Python_assignment_tops/Module 3/Given_key_Exit_in_Dictionary.py
Enter key in the d :5
NP

= RESTART: D:/C Data 16-02-24/Desktop/Python_assignment_tops/Module 3/Given_key_Exit_in_Dictionary.py
Enter key in the d :1
NP

= RESTART: D:/C Data 16-02-24/Desktop/Python_assignment_tops/Module 3/Given_key_Exit_in_Dictionary.py
Enter key in the d :1
dict_keys([1, 2, 3, 4, 5, 6])

= RESTART: D:/C Data 16-02-24/Desktop/Python_assignment_tops/Module 3/Given_key_Exit_in_Dictionary.py
Enter key in the d :2
NP

= RESTART: D:/C Data 16-02-24/Desktop/Python_assignment_tops/Module 3/Given_key_Exit_in_Dictionary.py
Enter key in the d :3
NP

= RESTART: D:/C Data 16-02-24/Desktop/Python_assignment_tops/Module 3/Given_key_Exit_in_Dictionary.py
Enter key in the d :4
P

= RESTART: D:/C Data 16-02-24/Desktop/Python_assignment_tops/Module 3/Given_key_Exit_in_Dictionary.py
Enter key in the d :11
NP

= RESTART: D:/C Data 16-02-24/Desktop/Python_assignment_tops/Module 3/Given_key_Exit_in_Dictionary.py
Enter key in the d :1
NP

= RESTART: D:/C Data 16-02-24/Desktop/Python_assignment_tops/Module 3/Given_key_Exit_in_Dictionary.py
Enter key in the d :
= RESTART: D:/C Data 16-02-24/Desktop/Python_assignment_tops/Module 3/Given_key_Exit_in_Dictionary.py
Enter key in the d :8
NP

= RESTART: D:/C Data 16-02-24/Desktop/Python_assignment_tops/Module 3/Given_key_Exit_in_Dictionary.py
Enter key in the d :2
Key is present

= RESTART: D:/C Data 16-02-24/Desktop/Python_assignment_tops/Module 3/Check_key_Exit_in_dictionary.py
dict_keys(['a', 'b', 'c', 'd'])

= RESTART: D:/C Data 16-02-24/Desktop/Python_assignment_tops/Module 3/Check_key_Exit_in_dictionary.py
dict_keys(['a', 'b', 'c', 'd'])
Enter key :a
Present : 100

= RESTART: D:/C Data 16-02-24/Desktop/Python_assignment_tops/Module 3/Check_key_Exit_in_dictionary.py
dict_keys(['a', 'b', 'c', 'd'])
Enter key :a
Present : a 100

= RESTART: D:/C Data 16-02-24/Desktop/Python_assignment_tops/Module 3/Check_key_Exit_in_dictionary.py
dict_keys(['a', 'b', 'c', 'd'])
Enter key :hjh
Not present

= RESTART: D:/C Data 16-02-24/Desktop/Python_assignment_tops/Module 3/Check_key_Exit_in_dictionary.py
dict_keys(['a', 'b', 'c', 'd'])
Enter key :c
Present :

= RESTART: D:/C Data 16-02-24/Desktop/Python_assignment_tops/Module 3/print_dictionary_kers_number_between_1_to_15.py
{1: 1, 2: 4, 3: 9, 4: 16, 5: 25, 6: 36, 7: 49, 8: 64, 9: 81, 10: 100, 11: 121, 12: 144, 13: 169, 14: 196, 15: 225}

= RESTART: D:/C Data 16-02-24/Desktop/Python_assignment_tops/Module 3/Check_Multiple_key_exit_in_dictionary.py
{'a': 'Tops', 'b': 'Technologies', 'c': 'Ahmedabad', 'd': 'iscon'}

= RESTART: D:/C Data 16-02-24/Desktop/Python_assignment_tops/Module 3/Check_Multiple_key_exit_in_dictionary.py
Traceback (most recent call last):
  File "D:/C Data 16-02-24/Desktop/Python_assignment_tops/Module 3/Check_Multiple_key_exit_in_dictionary.py", line 5, in <module>
    print(d.key('a'))
AttributeError: 'dict' object has no attribute 'key'. Did you mean: 'keys'?

= RESTART: D:/C Data 16-02-24/Desktop/Python_assignment_tops/Module 3/Check_Multiple_key_exit_in_dictionary.py
Tops

= RESTART: D:/C Data 16-02-24/Desktop/Python_assignment_tops/Module 3/Check_Multiple_key_exit_in_dictionary.py
Tops Technologies

= RESTART: D:/C Data 16-02-24/Desktop/Python_assignment_tops/Module 3/Check_Multiple_key_exit_in_dictionary.py
True

= RESTART: D:/C Data 16-02-24/Desktop/Python_assignment_tops/Module 3/Check_Multiple_key_exit_in_dictionary.py
True

= RESTART: D:/C Data 16-02-24/Desktop/Python_assignment_tops/Module 3/Check_Multiple_key_exit_in_dictionary.py
True
False

= RESTART: D:/C Data 16-02-24/Desktop/Python_assignment_tops/Module 3/Check_Multiple_key_exit_in_dictionary.py
True
False
Traceback (most recent call last):
  File "D:/C Data 16-02-24/Desktop/Python_assignment_tops/Module 3/Check_Multiple_key_exit_in_dictionary.py", line 7, in <module>
    print(d.keys('a','b','c'))
TypeError: dict.keys() takes no arguments (3 given)

= RESTART: D:/C Data 16-02-24/Desktop/Python_assignment_tops/Module 3/Check_Multiple_key_exit_in_dictionary.py
True
False
Traceback (most recent call last):
  File "D:/C Data 16-02-24/Desktop/Python_assignment_tops/Module 3/Check_Multiple_key_exit_in_dictionary.py", line 7, in <module>
    print(d.key('a','b','c'))
AttributeError: 'dict' object has no attribute 'key'. Did you mean: 'keys'?

= RESTART: D:/C Data 16-02-24/Desktop/Python_assignment_tops/Module 3/Check_Multiple_key_exit_in_dictionary.py
True
False
Traceback (most recent call last):
  File "D:/C Data 16-02-24/Desktop/Python_assignment_tops/Module 3/Check_Multiple_key_exit_in_dictionary.py", line 7, in <module>
    print(d.key['a','b','c'])
AttributeError: 'dict' object has no attribute 'key'. Did you mean: 'keys'?

= RESTART: D:/C Data 16-02-24/Desktop/Python_assignment_tops/Module 3/Check_Multiple_key_exit_in_dictionary.py
True
False
Traceback (most recent call last):
  File "D:/C Data 16-02-24/Desktop/Python_assignment_tops/Module 3/Check_Multiple_key_exit_in_dictionary.py", line 7, in <module>
    print(d.keys['a','b','c'])
TypeError: 'builtin_function_or_method' object is not subscriptable

= RESTART: D:/C Data 16-02-24/Desktop/Python_assignment_tops/Module 3/Check_Multiple_key_exit_in_dictionary.py
True
False
Traceback (most recent call last):
  File "D:/C Data 16-02-24/Desktop/Python_assignment_tops/Module 3/Check_Multiple_key_exit_in_dictionary.py", line 7, in <module>
    print(d['a','b','c'])
KeyError: ('a', 'b', 'c')

= RESTART: D:/C Data 16-02-24/Desktop/Python_assignment_tops/Module 3/Check_Multiple_key_exit_in_dictionary.py
True
False
Traceback (most recent call last):
  File "D:/C Data 16-02-24/Desktop/Python_assignment_tops/Module 3/Check_Multiple_key_exit_in_dictionary.py", line 7, in <module>
    print(d[a])
NameError: name 'a' is not defined

= RESTART: D:/C Data 16-02-24/Desktop/Python_assignment_tops/Module 3/Check_Multiple_key_exit_in_dictionary.py
True
False
Tops

= RESTART: D:/C Data 16-02-24/Desktop/Python_assignment_tops/Module 3/Check_Multiple_key_exit_in_dictionary.py
True
False
Traceback (most recent call last):
  File "D:/C Data 16-02-24/Desktop/Python_assignment_tops/Module 3/Check_Multiple_key_exit_in_dictionary.py", line 7, in <module>
    print(d['a'>'b'])
KeyError: False

= RESTART: D:/C Data 16-02-24/Desktop/Python_assignment_tops/Module 3/Check_Multiple_key_exit_in_dictionary.py
True
False
Traceback (most recent call last):
  File "D:/C Data 16-02-24/Desktop/Python_assignment_tops/Module 3/Check_Multiple_key_exit_in_dictionary.py", line 7, in <module>
    print(d['a' | 'b'])
TypeError: unsupported operand type(s) for |: 'str' and 'str'

= RESTART: D:/C Data 16-02-24/Desktop/Python_assignment_tops/Module 3/Check_Multiple_key_exit_in_dictionary.py
True
False
Traceback (most recent call last):
  File "D:/C Data 16-02-24/Desktop/Python_assignment_tops/Module 3/Check_Multiple_key_exit_in_dictionary.py", line 7, in <module>
    print(d['a' ,'b'])
KeyError: ('a', 'b')

= RESTART: D:/C Data 16-02-24/Desktop/Python_assignment_tops/Module 3/Check_Multiple_key_exit_in_dictionary.py
True
False

= RESTART: D:\C Data 16-02-24\Desktop\Python_assignment_tops\Module 3\Unzip_list_of_tuple.py
[(10, 30, 50, 70), (20, 40, 60, 80)]

= RESTART: D:/C Data 16-02-24/Desktop/Python_assignment_tops/Module 3/Merge_two_dictionery.py
Traceback (most recent call last):
  File "D:/C Data 16-02-24/Desktop/Python_assignment_tops/Module 3/Merge_two_dictionery.py", line 4, in <module>
    d1=d1.copy(d2)
TypeError: dict.copy() takes no arguments (1 given)

= RESTART: D:/C Data 16-02-24/Desktop/Python_assignment_tops/Module 3/Merge_two_dictionery.py
{'e': 500, 'f': 500, 'g': 600, 'h': 700}

= RESTART: D:/C Data 16-02-24/Desktop/Python_assignment_tops/Module 3/Merge_two_dictionery.py
{'e': 500, 'f': 500, 'g': 600, 'h': 700}

= RESTART: D:/C Data 16-02-24/Desktop/Python_assignment_tops/Module 3/Merge_two_dictionery.py
{<zip object at 0x00000161F4AAB280>}

= RESTART: D:/C Data 16-02-24/Desktop/Python_assignment_tops/Module 3/Merge_two_dictionery.py
{<zip object at 0x000002B77B17B280>}

= RESTART: D:/C Data 16-02-24/Desktop/Python_assignment_tops/Module 3/Merge_two_dictionery.py
{'a': 100, 'b': 200, 'c': 300, 'd': 400}

= RESTART: D:/C Data 16-02-24/Desktop/Python_assignment_tops/Module 3/Merge_two_dictionery.py
{'a': 100, 'b': 200, 'c': 300, 'd': 400, 'e': 500, 'f': 500, 'g': 600, 'h': 700}

= RESTART: D:/C Data 16-02-24/Desktop/Python_assignment_tops/Module 3/Merge_two_dictionery.py
None

= RESTART: D:/C Data 16-02-24/Desktop/Python_assignment_tops/Module 3/Merge_two_dictionery.py
{'a': 100, 'b': 200, 'c': 300, 'd': 400, 'e': 500, 'f': 500, 'g': 600, 'h': 700}

= RESTART: D:/C Data 16-02-24/Desktop/Python_assignment_tops/Module 3/Map_two_list_into_dictionary.py
Traceback (most recent call last):
  File "D:/C Data 16-02-24/Desktop/Python_assignment_tops/Module 3/Map_two_list_into_dictionary.py", line 5, in <module>
    d=zip[key,values]
TypeError: type 'zip' is not subscriptable

= RESTART: D:/C Data 16-02-24/Desktop/Python_assignment_tops/Module 3/Map_two_list_into_dictionary.py
<zip object at 0x0000022D69CCB280>

= RESTART: D:/C Data 16-02-24/Desktop/Python_assignment_tops/Module 3/Map_two_list_into_dictionary.py
<zip object at 0x00000189FCCAB280>

= RESTART: D:/C Data 16-02-24/Desktop/Python_assignment_tops/Module 3/Map_two_list_into_dictionary.py
<zip object at 0x000001AAEE04B280>

= RESTART: D:/C Data 16-02-24/Desktop/Python_assignment_tops/Module 3/Map_two_list_into_dictionary.py
{<zip object at 0x000002140A4BB280>}

= RESTART: D:/C Data 16-02-24/Desktop/Python_assignment_tops/Module 3/Map_two_list_into_dictionary.py
Traceback (most recent call last):
  File "D:/C Data 16-02-24/Desktop/Python_assignment_tops/Module 3/Map_two_list_into_dictionary.py", line 6, in <module>
    for k,v in (key,values):
ValueError: too many values to unpack (expected 2)

= RESTART: D:/C Data 16-02-24/Desktop/Python_assignment_tops/Module 3/Map_two_list_into_dictionary.py
{1: 101, 2: 201, 3: 301, 4: 401, 5: 501, 6: 601}

= RESTART: D:/C Data 16-02-24/Desktop/Python_assignment_tops/Module 3/Map_two_list_into_dictionary.py
<zip object at 0x000002444B09B280>

= RESTART: D:/C Data 16-02-24/Desktop/Python_assignment_tops/Module 3/Map_two_list_into_dictionary.py
[<zip object at 0x000001DBAE34B280>]

= RESTART: D:/C Data 16-02-24/Desktop/Python_assignment_tops/Module 3/Map_two_list_into_dictionary.py
{1: 101, 2: 201, 3: 301, 4: 401, 5: 501, 6: 601}

= RESTART: D:/C Data 16-02-24/Desktop/Python_assignment_tops/Module 3/Map_two_list_into_dictionary.py
Traceback (most recent call last):
  File "D:/C Data 16-02-24/Desktop/Python_assignment_tops/Module 3/Map_two_list_into_dictionary.py", line 5, in <module>
    d1=[{key:values}for key in key for values in values]
UnboundLocalError: cannot access local variable 'values' where it is not associated with a value

= RESTART: D:/C Data 16-02-24/Desktop/Python_assignment_tops/Module 3/Map_two_list_into_dictionary.py
Traceback (most recent call last):
  File "D:/C Data 16-02-24/Desktop/Python_assignment_tops/Module 3/Map_two_list_into_dictionary.py", line 5, in <module>
    d1={key:values for key in key for values in values}
UnboundLocalError: cannot access local variable 'values' where it is not associated with a value

= RESTART: D:/C Data 16-02-24/Desktop/Python_assignment_tops/Module 3/Map_two_list_into_dictionary.py
Traceback (most recent call last):
  File "D:/C Data 16-02-24/Desktop/Python_assignment_tops/Module 3/Map_two_list_into_dictionary.py", line 5, in <module>
    d1={key:values for key in key for values in values}
UnboundLocalError: cannot access local variable 'values' where it is not associated with a value

= RESTART: D:/C Data 16-02-24/Desktop/Python_assignment_tops/Module 3/Map_two_list_into_dictionary.py
Traceback (most recent call last):
  File "D:/C Data 16-02-24/Desktop/Python_assignment_tops/Module 3/Map_two_list_into_dictionary.py", line 5, in <module>
    d1={k:v for k in keu for v in values}
NameError: name 'keu' is not defined. Did you mean: 'key'?

= RESTART: D:/C Data 16-02-24/Desktop/Python_assignment_tops/Module 3/Map_two_list_into_dictionary.py
{1: 601, 2: 601, 3: 601, 4: 601, 5: 601, 6: 601}

= RESTART: D:/C Data 16-02-24/Desktop/Python_assignment_tops/Module 3/Map_two_list_into_dictionary.py
{1: 601, 2: 601, 3: 601, 4: 601, 5: 601, 6: 601}
{1: 101, 2: 201, 3: 301, 4: 401, 5: 501, 6: 601}

= RESTART: D:/C Data 16-02-24/Desktop/Python_assignment_tops/Module 3/Map_two_list_into_dictionary.py
{1: 601, 2: 601, 3: 601, 4: 601, 5: 601, 6: 601}
Traceback (most recent call last):
  File "D:/C Data 16-02-24/Desktop/Python_assignment_tops/Module 3/Map_two_list_into_dictionary.py", line 8, in <module>
    print(kv)
NameError: name 'kv' is not defined. Did you mean: 'k'?

= RESTART: D:/C Data 16-02-24/Desktop/Python_assignment_tops/Module 3/Map_two_list_into_dictionary.py
{1: 601, 2: 601, 3: 601, 4: 601, 5: 601, 6: 601}
1
2
3
4
5
6

= RESTART: D:/C Data 16-02-24/Desktop/Python_assignment_tops/Module 3/Map_two_list_into_dictionary.py
{1: 601, 2: 601, 3: 601, 4: 601, 5: 601, 6: 601}
1 101
2 201
3 301
4 401
5 501
6 601

= RESTART: D:/C Data 16-02-24/Desktop/Python_assignment_tops/Module 3/Map_two_list_into_dictionary.py
Traceback (most recent call last):
  File "D:/C Data 16-02-24/Desktop/Python_assignment_tops/Module 3/Map_two_list_into_dictionary.py", line 6, in <module>
    print(k,v)
NameError: name 'k' is not defined

= RESTART: D:/C Data 16-02-24/Desktop/Python_assignment_tops/Module 3/Map_two_list_into_dictionary.py
{1: 601, 2: 601, 3: 601, 4: 601, 5: 601, 6: 601}
1 101
2 201
3 301
4 401
5 501
6 601

= RESTART: D:/C Data 16-02-24/Desktop/Python_assignment_tops/Module 3/Map_two_list_into_dictionary.py
{1: 601, 2: 601, 3: 601, 4: 601, 5: 601, 6: 601}
Traceback (most recent call last):
  File "D:/C Data 16-02-24/Desktop/Python_assignment_tops/Module 3/Map_two_list_into_dictionary.py", line 8, in <module>
    d[k]=v
NameError: name 'd' is not defined. Did you mean: 'd1'?

= RESTART: D:/C Data 16-02-24/Desktop/Python_assignment_tops/Module 3/Map_two_list_into_dictionary.py
Traceback (most recent call last):
  File "D:/C Data 16-02-24/Desktop/Python_assignment_tops/Module 3/Map_two_list_into_dictionary.py", line 6, in <module>
    d[k]=v
NameError: name 'd' is not defined. Did you mean: 'id'?

= RESTART: D:/C Data 16-02-24/Desktop/Python_assignment_tops/Module 3/Map_two_list_into_dictionary.py
Traceback (most recent call last):
  File "D:/C Data 16-02-24/Desktop/Python_assignment_tops/Module 3/Map_two_list_into_dictionary.py", line 6, in <module>
    d1[k]=v
NameError: name 'd1' is not defined

= RESTART: D:/C Data 16-02-24/Desktop/Python_assignment_tops/Module 3/Map_two_list_into_dictionary.py
{1: 101, 2: 201, 3: 301, 4: 401, 5: 501, 6: 601}

= RESTART: D:/C Data 16-02-24/Desktop/Python_assignment_tops/Module 3/Map_two_list_into_dictionary.py
{1: 101, 2: 201, 3: 301, 4: 401, 5: 501, 6: 601}
{1: 601, 2: 601, 3: 601, 4: 601, 5: 601, 6: 601}

= RESTART: D:/C Data 16-02-24/Desktop/Python_assignment_tops/Module 3/Map_two_list_into_dictionary.py
{1: 101, 2: 201, 3: 301, 4: 401, 5: 501, 6: 601}
*************second method**************

= RESTART: D:/C Data 16-02-24/Desktop/Python_assignment_tops/Module 3/Map_two_list_into_dictionary.py
{1: 101, 2: 201, 3: 301, 4: 401, 5: 501, 6: 601}
*************second method**************
{1: 601, 2: 601, 3: 601, 4: 601, 5: 601, 6: 601}

= RESTART: D:/C Data 16-02-24/Desktop/Python_assignment_tops/Module 3/sum_of_two_dictionary.py
Traceback (most recent call last):
  File "D:/C Data 16-02-24/Desktop/Python_assignment_tops/Module 3/sum_of_two_dictionary.py", line 5, in <module>
    from collections import Operator as sum
ImportError: cannot import name 'Operator' from 'collections' (C:\Users\_\AppData\Local\Programs\Python\Python312\Lib\collections\__init__.py)

= RESTART: D:/C Data 16-02-24/Desktop/Python_assignment_tops/Module 3/sum_of_two_dictionary.py
Traceback (most recent call last):
  File "D:/C Data 16-02-24/Desktop/Python_assignment_tops/Module 3/sum_of_two_dictionary.py", line 5, in <module>
    from collactions import Operator as sum
ModuleNotFoundError: No module named 'collactions'

= RESTART: D:/C Data 16-02-24/Desktop/Python_assignment_tops/Module 3/sum_of_two_dictionary.py
Traceback (most recent call last):
  File "D:/C Data 16-02-24/Desktop/Python_assignment_tops/Module 3/sum_of_two_dictionary.py", line 5, in <module>
    from collections import Operator as sum
ImportError: cannot import name 'Operator' from 'collections' (C:\Users\_\AppData\Local\Programs\Python\Python312\Lib\collections\__init__.py)

= RESTART: D:/C Data 16-02-24/Desktop/Python_assignment_tops/Module 3/sum_of_two_dictionary.py
Counter({'a': 400, 'b': 400, 'd': 400, 'c': 300})

= RESTART: D:/C Data 16-02-24/Desktop/Python_assignment_tops/Module 3/sum_of_two_dictionary.py
['a', 'b', 'c', 'd']

= RESTART: D:/C Data 16-02-24/Desktop/Python_assignment_tops/Module 3/sum_of_two_dictionary.py
['a', 'b', 'c', 'd']

= RESTART: D:/C Data 16-02-24/Desktop/Python_assignment_tops/Module 3/sum_of_two_dictionary.py
Traceback (most recent call last):
  File "D:/C Data 16-02-24/Desktop/Python_assignment_tops/Module 3/sum_of_two_dictionary.py", line 8, in <module>
    d3= {sum(d1) + sum(d2)}
TypeError: unhashable type: 'Counter'

= RESTART: D:/C Data 16-02-24/Desktop/Python_assignment_tops/Module 3/sum_of_two_dictionary.py
['a', 'b', 'c', 'd']

= RESTART: D:/C Data 16-02-24/Desktop/Python_assignment_tops/Module 3/sum_of_two_dictionary.py
{'a': 400, 'b': 400, 'c': 300, 'd': 400}

= RESTART: D:/C Data 16-02-24/Desktop/Python_assignment_tops/Module 3/sum_of_two_dictionary.py
{'a': 400, 'b': 1000, 'c': 300, 'd': 400}

= RESTART: D:/C Data 16-02-24/Desktop/Python_assignment_tops/Module 3/print_all_unique_values_in_dictionary.py
{'a': 10, 'b': 20, 'c': 30, 'd': 10, 'e': 20, 'f': 'Tops', 'g': 'Tops'}

= RESTART: D:/C Data 16-02-24/Desktop/Python_assignment_tops/Module 3/print_all_unique_values_in_dictionary.py
10
20
30
10
20
Tops
Tops

= RESTART: D:/C Data 16-02-24/Desktop/Python_assignment_tops/Module 3/print_all_unique_values_in_dictionary.py
a
b
c
d
e
f
g

= RESTART: D:/C Data 16-02-24/Desktop/Python_assignment_tops/Module 3/print_all_unique_values_in_dictionary.py
Traceback (most recent call last):
  File "D:/C Data 16-02-24/Desktop/Python_assignment_tops/Module 3/print_all_unique_values_in_dictionary.py", line 3, in <module>
    for i in zip(d.keys(),k.values()) :
NameError: name 'k' is not defined

= RESTART: D:/C Data 16-02-24/Desktop/Python_assignment_tops/Module 3/print_all_unique_values_in_dictionary.py
('a', 10)
('b', 20)
('c', 30)
('d', 10)
('e', 20)
('f', 'Tops')
('g', 'Tops')

= RESTART: D:/C Data 16-02-24/Desktop/Python_assignment_tops/Module 3/print_all_unique_values_in_dictionary.py
Traceback (most recent call last):
  File "D:/C Data 16-02-24/Desktop/Python_assignment_tops/Module 3/print_all_unique_values_in_dictionary.py", line 5, in <module>
    if m not in d:
NameError: name 'm' is not defined

= RESTART: D:/C Data 16-02-24/Desktop/Python_assignment_tops/Module 3/print_all_unique_values_in_dictionary.py
Traceback (most recent call last):
  File "D:/C Data 16-02-24/Desktop/Python_assignment_tops/Module 3/print_all_unique_values_in_dictionary.py", line 6, in <module>
    u,update(i)
NameError: name 'update' is not defined

= RESTART: D:/C Data 16-02-24/Desktop/Python_assignment_tops/Module 3/print_all_unique_values_in_dictionary.py
Traceback (most recent call last):
  File "D:/C Data 16-02-24/Desktop/Python_assignment_tops/Module 3/print_all_unique_values_in_dictionary.py", line 6, in <module>
    u.update(i)
ValueError: dictionary update sequence element #0 has length 1; 2 is required

= RESTART: D:/C Data 16-02-24/Desktop/Python_assignment_tops/Module 3/print_all_unique_values_in_dictionary.py
Traceback (most recent call last):
  File "D:/C Data 16-02-24/Desktop/Python_assignment_tops/Module 3/print_all_unique_values_in_dictionary.py", line 6, in <module>
    u.update(i)
ValueError: dictionary update sequence element #0 has length 1; 2 is required

= RESTART: D:/C Data 16-02-24/Desktop/Python_assignment_tops/Module 3/print_all_unique_values_in_dictionary.py
Traceback (most recent call last):
  File "D:/C Data 16-02-24/Desktop/Python_assignment_tops/Module 3/print_all_unique_values_in_dictionary.py", line 6, in <module>
    u.update(i)
ValueError: dictionary update sequence element #0 has length 1; 2 is required

= RESTART: D:/C Data 16-02-24/Desktop/Python_assignment_tops/Module 3/print_all_unique_values_in_dictionary.py
Traceback (most recent call last):
  File "D:/C Data 16-02-24/Desktop/Python_assignment_tops/Module 3/print_all_unique_values_in_dictionary.py", line 7, in <module>
    print("All unoque values : ",dict(u))
TypeError: cannot convert dictionary update sequence element #0 to a sequence

= RESTART: D:/C Data 16-02-24/Desktop/Python_assignment_tops/Module 3/print_all_unique_values_in_dictionary.py
All unoque values :  [10, 20, 30, 'Tops']

= RESTART: D:/C Data 16-02-24/Desktop/Python_assignment_tops/Module 3/print_all_unique_values_in_dictionary.py
Traceback (most recent call last):
  File "D:/C Data 16-02-24/Desktop/Python_assignment_tops/Module 3/print_all_unique_values_in_dictionary.py", line 7, in <module>
    u.append(i)
AttributeError: 'dict' object has no attribute 'append'

= RESTART: D:/C Data 16-02-24/Desktop/Python_assignment_tops/Module 3/print_all_unique_values_in_dictionary.py
Traceback (most recent call last):
  File "D:/C Data 16-02-24/Desktop/Python_assignment_tops/Module 3/print_all_unique_values_in_dictionary.py", line 7, in <module>
    u.append(i)
AttributeError: 'dict' object has no attribute 'append'

= RESTART: D:/C Data 16-02-24/Desktop/Python_assignment_tops/Module 3/print_all_unique_values_in_dictionary.py
Unique values in the dictionary:  [10, 20, 30, 'Tops']

= RESTART: D:/C Data 16-02-24/Desktop/Python_assignment_tops/Module 3/print_all_unique_values_in_dictionary.py
Unique values in the dictionary:  [10, 20, 30, 'Tops']

= RESTART: D:/C Data 16-02-24/Desktop/Python_assignment_tops/Module 3/How_to_use_zip_in_python.py
{'a': 100, 'b': 200, 'c': 300, 'd': 400, 'e': 500, 'f': 600, 'g': 700}

= RESTART: D:/C Data 16-02-24/Desktop/Python_assignment_tops/Module 3/select_each_letter_select_another_dict_letter.py
{'1': ['a', 'b'], '2': ['c', 'd']}

= RESTART: D:/C Data 16-02-24/Desktop/Python_assignment_tops/Module 3/select_each_letter_select_another_dict_letter.py
Traceback (most recent call last):
  File "D:/C Data 16-02-24/Desktop/Python_assignment_tops/Module 3/select_each_letter_select_another_dict_letter.py", line 7, in <module>
    print(d[0])
KeyError: 0

= RESTART: D:/C Data 16-02-24/Desktop/Python_assignment_tops/Module 3/select_each_letter_select_another_dict_letter.py
Traceback (most recent call last):
  File "D:/C Data 16-02-24/Desktop/Python_assignment_tops/Module 3/select_each_letter_select_another_dict_letter.py", line 7, in <module>
    print(d[1])
KeyError: 1

= RESTART: D:/C Data 16-02-24/Desktop/Python_assignment_tops/Module 3/select_each_letter_select_another_dict_letter.py
['a', 'b']

= RESTART: D:/C Data 16-02-24/Desktop/Python_assignment_tops/Module 3/select_each_letter_select_another_dict_letter.py
['a', 'b']

= RESTART: D:/C Data 16-02-24/Desktop/Python_assignment_tops/Module 3/select_each_letter_select_another_dict_letter.py
{'1': ['a', 'b'], '2': ['c', 'd']}
{'1': ['a', 'b'], '2': ['c', 'd']}

= RESTART: D:/C Data 16-02-24/Desktop/Python_assignment_tops/Module 3/select_each_letter_select_another_dict_letter.py
{'1': ['a', 'b'], '2': ['c', 'd']}
{'1': ['a', 'b'], '2': ['c', 'd']}

= RESTART: D:/C Data 16-02-24/Desktop/Python_assignment_tops/Module 3/select_each_letter_select_another_dict_letter.py
1
2

= RESTART: D:/C Data 16-02-24/Desktop/Python_assignment_tops/Module 3/select_each_letter_select_another_dict_letter.py
('1', ['a', 'b'])
('2', ['c', 'd'])

= RESTART: D:/C Data 16-02-24/Desktop/Python_assignment_tops/Module 3/select_each_letter_select_another_dict_letter.py
<class 'tuple'>
<class 'tuple'>

= RESTART: D:/C Data 16-02-24/Desktop/Python_assignment_tops/Module 3/select_each_letter_select_another_dict_letter.py
1
2

= RESTART: D:/C Data 16-02-24/Desktop/Python_assignment_tops/Module 3/select_each_letter_select_another_dict_letter.py
['a', 'b']
['c', 'd']

= RESTART: D:/C Data 16-02-24/Desktop/Python_assignment_tops/Module 3/select_each_letter_select_another_dict_letter.py
ac
ad
bc
bd

= RESTART: D:/C Data 16-02-24/Desktop/Python_assignment_tops/Module 3/select_each_letter_select_another_dict_letter.py
ac
ad
bc
bd
bd

= RESTART: D:/C Data 16-02-24/Desktop/Python_assignment_tops/Module 3/select_each_letter_select_another_dict_letter.py
bd

= RESTART: D:/C Data 16-02-24/Desktop/Python_assignment_tops/Module 3/select_each_letter_select_another_dict_letter.py
ad
bd

= RESTART: D:/C Data 16-02-24/Desktop/Python_assignment_tops/Module 3/select_each_letter_select_another_dict_letter.py
Traceback (most recent call last):
  File "D:/C Data 16-02-24/Desktop/Python_assignment_tops/Module 3/select_each_letter_select_another_dict_letter.py", line 8, in <module>
    print(d[0])
KeyError: 0

= RESTART: D:/C Data 16-02-24/Desktop/Python_assignment_tops/Module 3/select_each_letter_select_another_dict_letter.py
Traceback (most recent call last):
  File "D:/C Data 16-02-24/Desktop/Python_assignment_tops/Module 3/select_each_letter_select_another_dict_letter.py", line 8, in <module>
    print(d[1])
KeyError: 1

= RESTART: D:/C Data 16-02-24/Desktop/Python_assignment_tops/Module 3/select_each_letter_select_another_dict_letter.py
['a', 'b']

= RESTART: D:/C Data 16-02-24/Desktop/Python_assignment_tops/Module 3/select_each_letter_select_another_dict_letter.py
a

= RESTART: D:/C Data 16-02-24/Desktop/Python_assignment_tops/Module 3/select_each_letter_select_another_dict_letter.py
b

= RESTART: D:/C Data 16-02-24/Desktop/Python_assignment_tops/Module 3/select_each_letter_select_another_dict_letter.py
Traceback (most recent call last):
  File "D:/C Data 16-02-24/Desktop/Python_assignment_tops/Module 3/select_each_letter_select_another_dict_letter.py", line 8, in <module>
    print(d['1'][1])
KeyError: '1'

= RESTART: D:/C Data 16-02-24/Desktop/Python_assignment_tops/Module 3/select_each_letter_select_another_dict_letter.py
b
2
3
3
4

= RESTART: D:/C Data 16-02-24/Desktop/Python_assignment_tops/Module 3/select_each_letter_select_another_dict_letter.py
2
3
3
4

= RESTART: D:/C Data 16-02-24/Desktop/Python_assignment_tops/Module 3/select_each_letter_select_another_dict_letter.py
Traceback (most recent call last):
  File "D:/C Data 16-02-24/Desktop/Python_assignment_tops/Module 3/select_each_letter_select_another_dict_letter.py", line 9, in <module>
    for i in d.values:
TypeError: 'builtin_function_or_method' object is not iterable

= RESTART: D:/C Data 16-02-24/Desktop/Python_assignment_tops/Module 3/select_each_letter_select_another_dict_letter.py
['a', 'b', 'a', 'b']
['a', 'b', 'c', 'd']
['c', 'd', 'a', 'b']
['c', 'd', 'c', 'd']

= RESTART: D:/C Data 16-02-24/Desktop/Python_assignment_tops/Module 3/select_each_letter_select_another_dict_letter.py
ac
ad
bc
bd

= RESTART: D:/C Data 16-02-24/Desktop/Python_assignment_tops/Module 3/select_each_letter_select_another_dict_letter.py
['a', 'b']
ac
ad
bc
bd

= RESTART: D:/C Data 16-02-24/Desktop/Python_assignment_tops/Module 3/select_each_letter_select_another_dict_letter.py
['a', 'b']
a
b

= RESTART: D:/C Data 16-02-24/Desktop/Python_assignment_tops/Module 3/select_each_letter_select_another_dict_letter.py
ac
ad
bc
bd

= RESTART: D:/C Data 16-02-24/Desktop/Python_assignment_tops/Module 3/select_each_letter_select_another_dict_letter.py
ace
acf
ade
adf
bce
bcf
bde
bdf

= RESTART: D:/C Data 16-02-24/Desktop/Python_assignment_tops/Module 3/select_each_letter_select_another_dict_letter.py
ac
ad
bc
bd

= RESTART: D:/C Data 16-02-24/Desktop/Python_assignment_tops/Module 3/Find_max_3_values_in_dictionary.py
{'a': 56, 'b': 77, 'c': 21, 'd': 99, 'e': 121, 'f': 66}

= RESTART: D:/C Data 16-02-24/Desktop/Python_assignment_tops/Module 3/Find_max_3_values_in_dictionary.py
56
77
21
99
121
66

= RESTART: D:/C Data 16-02-24/Desktop/Python_assignment_tops/Module 3/Find_max_3_values_in_dictionary.py
Traceback (most recent call last):
  File "D:/C Data 16-02-24/Desktop/Python_assignment_tops/Module 3/Find_max_3_values_in_dictionary.py", line 4, in <module>
    print(max(i))
TypeError: 'int' object is not iterable

= RESTART: D:/C Data 16-02-24/Desktop/Python_assignment_tops/Module 3/Find_max_3_values_in_dictionary.py
[56, 77, 21, 99, 121, 66]

= RESTART: D:/C Data 16-02-24/Desktop/Python_assignment_tops/Module 3/Find_max_3_values_in_dictionary.py
[56, 77, 21, 99, 121, 66]

= RESTART: D:/C Data 16-02-24/Desktop/Python_assignment_tops/Module 3/Find_max_3_values_in_dictionary.py

= RESTART: D:/C Data 16-02-24/Desktop/Python_assignment_tops/Module 3/Find_max_3_values_in_dictionary.py
121

= RESTART: D:/C Data 16-02-24/Desktop/Python_assignment_tops/Module 3/Find_max_3_values_in_dictionary.py
121
56
77
21
99
121
66

= RESTART: D:/C Data 16-02-24/Desktop/Python_assignment_tops/Module 3/Find_max_3_values_in_dictionary.py
['a', 'b', 'c', 'd', 'e', 'f']

= RESTART: D:/C Data 16-02-24/Desktop/Python_assignment_tops/Module 3/Find_max_3_values_in_dictionary.py
[21, 56, 66, 77, 99, 121]

= RESTART: D:/C Data 16-02-24/Desktop/Python_assignment_tops/Module 3/Find_max_3_values_in_dictionary.py
[121, 99, 77, 66, 56, 21]

= RESTART: D:/C Data 16-02-24/Desktop/Python_assignment_tops/Module 3/Find_max_3_values_in_dictionary.py
[121, 99, 77, 66, 56, 21]

= RESTART: D:/C Data 16-02-24/Desktop/Python_assignment_tops/Module 3/Find_max_3_values_in_dictionary.py
Traceback (most recent call last):
  File "D:/C Data 16-02-24/Desktop/Python_assignment_tops/Module 3/Find_max_3_values_in_dictionary.py", line 3, in <module>
    m=dict((sorted(d.values(),reverse=True)))
TypeError: cannot convert dictionary update sequence element #0 to a sequence

= RESTART: D:/C Data 16-02-24/Desktop/Python_assignment_tops/Module 3/Find_max_3_values_in_dictionary.py
Traceback (most recent call last):
  File "D:/C Data 16-02-24/Desktop/Python_assignment_tops/Module 3/Find_max_3_values_in_dictionary.py", line 3, in <module>
    m=dict((sorted(d.values(),reverse=True)))
TypeError: cannot convert dictionary update sequence element #0 to a sequence

= RESTART: D:/C Data 16-02-24/Desktop/Python_assignment_tops/Module 3/Find_max_3_values_in_dictionary.py
[121, 99, 77, 66, 56, 21]

= RESTART: D:/C Data 16-02-24/Desktop/Python_assignment_tops/Module 3/Find_max_3_values_in_dictionary.py
[121, 99, 77, 66]

= RESTART: D:/C Data 16-02-24/Desktop/Python_assignment_tops/Module 3/Find_max_3_values_in_dictionary.py
[121, 99, 77]

= RESTART: D:/C Data 16-02-24/Desktop/Python_assignment_tops/Module 3/Find_max_3_values_in_dictionary.py
3 highest value :  [121, 99, 77]

= RESTART: D:/C Data 16-02-24/Desktop/Python_assignment_tops/Module 3/Same_value_of_dict_and_Pluse.py
[{'item': 'item1', 'amount': 400}, {'item': 'item2', 'amount': 300}, {'item': 'item1', 'amount': 750}]

= RESTART: D:/C Data 16-02-24/Desktop/Python_assignment_tops/Module 3/Same_value_of_dict_and_Pluse.py
{'item': 'item1', 'amount': 400}

= RESTART: D:/C Data 16-02-24/Desktop/Python_assignment_tops/Module 3/Same_value_of_dict_and_Pluse.py
Traceback (most recent call last):
  File "D:/C Data 16-02-24/Desktop/Python_assignment_tops/Module 3/Same_value_of_dict_and_Pluse.py", line 10, in <module>
    print(l[0][0])
KeyError: 0

= RESTART: D:/C Data 16-02-24/Desktop/Python_assignment_tops/Module 3/Same_value_of_dict_and_Pluse.py
Traceback (most recent call last):
  File "D:/C Data 16-02-24/Desktop/Python_assignment_tops/Module 3/Same_value_of_dict_and_Pluse.py", line 10, in <module>
    print(l[0][1])
KeyError: 1

Warning (from warnings module):
  File "D:/C Data 16-02-24/Desktop/Python_assignment_tops/Module 3/Same_value_of_dict_and_Pluse.py", line 10
    print(l[0[0]])
SyntaxWarning: 'int' object is not subscriptable; perhaps you missed a comma?
>>> 
= RESTART: D:/C Data 16-02-24/Desktop/Python_assignment_tops/Module 3/Same_value_of_dict_and_Pluse.py
Traceback (most recent call last):
  File "D:/C Data 16-02-24/Desktop/Python_assignment_tops/Module 3/Same_value_of_dict_and_Pluse.py", line 10, in <module>
    print(l[0[0]])
TypeError: 'int' object is not subscriptable

= RESTART: D:/C Data 16-02-24/Desktop/Python_assignment_tops/Module 3/Same_value_of_dict_and_Pluse.py
{'item': 'item1', 'amount': 400}

= RESTART: D:/C Data 16-02-24/Desktop/Python_assignment_tops/Module 3/Same_value_of_dict_and_Pluse.py
{'item': 'item1', 'amount': 400}
{'item': 'item2', 'amount': 300}
{'item': 'item1', 'amount': 750}

= RESTART: D:/C Data 16-02-24/Desktop/Python_assignment_tops/Module 3/Same_value_of_dict_and_Pluse.py
Traceback (most recent call last):
  File "D:/C Data 16-02-24/Desktop/Python_assignment_tops/Module 3/Same_value_of_dict_and_Pluse.py", line 12, in <module>
    print(i[0].items())
NameError: name 'i' is not defined. Did you mean: 'id'?

= RESTART: D:/C Data 16-02-24/Desktop/Python_assignment_tops/Module 3/Same_value_of_dict_and_Pluse.py
{'item1': 1150, 'item2': 300}

= RESTART: D:/C Data 16-02-24/Desktop/Python_assignment_tops/Module 3/Same_value_of_dict_and_Pluse.py
Traceback (most recent call last):
  File "D:/C Data 16-02-24/Desktop/Python_assignment_tops/Module 3/Same_value_of_dict_and_Pluse.py", line 15, in <module>
    print(d1[0])
KeyError: 0

= RESTART: D:/C Data 16-02-24/Desktop/Python_assignment_tops/Module 3/Same_value_of_dict_and_Pluse.py
{'item': 'item1', 'amount': 400}

= RESTART: D:/C Data 16-02-24/Desktop/Python_assignment_tops/Module 3/Same_value_of_dict_and_Pluse.py
{'item': 'item1', 'amount': 400}

= RESTART: D:/C Data 16-02-24/Desktop/Python_assignment_tops/Module 3/Same_value_of_dict_and_Pluse.py
<class 'dict'>

= RESTART: D:/C Data 16-02-24/Desktop/Python_assignment_tops/Module 3/Same_value_of_dict_and_Pluse.py
{'item': 'item1', 'amount': 400}
{'item': 'item2', 'amount': 300}
{'item': 'item1', 'amount': 750}

= RESTART: D:/C Data 16-02-24/Desktop/Python_assignment_tops/Module 3/Same_value_of_dict_and_Pluse.py
Traceback (most recent call last):
  File "D:/C Data 16-02-24/Desktop/Python_assignment_tops/Module 3/Same_value_of_dict_and_Pluse.py", line 15, in <module>
    for i in d.values():
AttributeError: 'list' object has no attribute 'values'

= RESTART: D:/C Data 16-02-24/Desktop/Python_assignment_tops/Module 3/Same_value_of_dict_and_Pluse.py
{'item': 'item1', 'amount': 400}
{'item': 'item2', 'amount': 300}
{'item': 'item1', 'amount': 750}

= RESTART: D:/C Data 16-02-24/Desktop/Python_assignment_tops/Module 3/Same_value_of_dict_and_Pluse.py
Traceback (most recent call last):
  File "D:/C Data 16-02-24/Desktop/Python_assignment_tops/Module 3/Same_value_of_dict_and_Pluse.py", line 16, in <module>
    print(l.values())
NameError: name 'l' is not defined

= RESTART: D:/C Data 16-02-24/Desktop/Python_assignment_tops/Module 3/Same_value_of_dict_and_Pluse.py
<class 'dict'>
<class 'dict'>
<class 'dict'>

= RESTART: D:/C Data 16-02-24/Desktop/Python_assignment_tops/Module 3/Same_value_of_dict_and_Pluse.py
dict_values(['item1', 400])
dict_values(['item2', 300])
dict_values(['item1', 750])

= RESTART: D:/C Data 16-02-24/Desktop/Python_assignment_tops/Module 3/Same_value_of_dict_and_Pluse.py
dict_keys(['item', 'amount'])
dict_keys(['item', 'amount'])
dict_keys(['item', 'amount'])

= RESTART: D:/C Data 16-02-24/Desktop/Python_assignment_tops/Module 3/Same_value_of_dict_and_Pluse.py
dict_keys(['item', 'amount'])
dict_values(['item1', 400])
dict_keys(['item', 'amount'])
dict_values(['item2', 300])
dict_keys(['item', 'amount'])
dict_values(['item1', 750])

= RESTART: D:/C Data 16-02-24/Desktop/Python_assignment_tops/Module 3/Same_value_of_dict_and_Pluse.py
{'item': 'item1', 'amount': 400}
{'item': 'item2', 'amount': 300}
{'item': 'item1', 'amount': 750}

= RESTART: D:/C Data 16-02-24/Desktop/Python_assignment_tops/Module 3/Same_value_of_dict_and_Pluse.py
item1
item2
item1
{'item1': 750}

= RESTART: D:/C Data 16-02-24/Desktop/Python_assignment_tops/Module 3/Same_value_of_dict_and_Pluse.py
400
300
750
{'item1': 750}

= RESTART: D:/C Data 16-02-24/Desktop/Python_assignment_tops/Module 3/Same_value_of_dict_and_Pluse.py
dict_values(['item1', 400])
dict_values(['item2', 300])
dict_values(['item1', 750])
{'item1': 750}

= RESTART: D:/C Data 16-02-24/Desktop/Python_assignment_tops/Module 3/Same_value_of_dict_and_Pluse.py
{'item1': 3450, 'item2': 900}

= RESTART: D:/C Data 16-02-24/Desktop/Python_assignment_tops/Module 3/Same_value_of_dict_and_Pluse.py
Traceback (most recent call last):
  File "D:/C Data 16-02-24/Desktop/Python_assignment_tops/Module 3/Same_value_of_dict_and_Pluse.py", line 10, in <module>
    from collactions import Counter as sum
ModuleNotFoundError: No module named 'collactions'

= RESTART: D:/C Data 16-02-24/Desktop/Python_assignment_tops/Module 3/Same_value_of_dict_and_Pluse.py
{'item': 'item1', 'amount': 400}
{'item': 'item2', 'amount': 300}
{'item': 'item1', 'amount': 750}

= RESTART: D:/C Data 16-02-24/Desktop/Python_assignment_tops/Module 3/Same_value_of_dict_and_Pluse.py
Traceback (most recent call last):
  File "D:/C Data 16-02-24/Desktop/Python_assignment_tops/Module 3/Same_value_of_dict_and_Pluse.py", line 12, in <module>
    print(sum(d))
  File "C:\Users\_\AppData\Local\Programs\Python\Python312\Lib\collections\__init__.py", line 607, in __init__
    self.update(iterable, **kwds)
  File "C:\Users\_\AppData\Local\Programs\Python\Python312\Lib\collections\__init__.py", line 698, in update
    _count_elements(self, iterable)
TypeError: unhashable type: 'dict'

= RESTART: D:/C Data 16-02-24/Desktop/Python_assignment_tops/Module 3/Same_value_of_dict_and_Pluse.py
{'item': 'item1', 'amount': 400}
{'item': 'item2', 'amount': 300}
{'item': 'item1', 'amount': 750}

= RESTART: D:/C Data 16-02-24/Desktop/Python_assignment_tops/Module 3/Same_value_of_dict_and_Pluse.py
{'item': 'item1', 'amount': 400}
{'item': 'item2', 'amount': 300}
{'item': 'item1', 'amount': 750}

= RESTART: D:/C Data 16-02-24/Desktop/Python_assignment_tops/Module 3/Same_value_of_dict_and_Pluse.py
{'item': 'item1', 'amount': 400}
{'item': 'item2', 'amount': 300}
{'item': 'item1', 'amount': 750}

= RESTART: D:/C Data 16-02-24/Desktop/Python_assignment_tops/Module 3/Same_value_of_dict_and_Pluse.py
{'item': 'item1', 'amount': 400}
{'item': 'item2', 'amount': 300}
{'item': 'item1', 'amount': 750}

= RESTART: D:/C Data 16-02-24/Desktop/Python_assignment_tops/Module 3/Same_value_of_dict_and_Pluse.py
Counter({'item1': 1150, 'item2': 300})

= RESTART: D:/C Data 16-02-24/Desktop/Python_assignment_tops/Module 3/Same_value_of_dict_and_Pluse.py
Counter({'item1': 1150, 'item2': 300})

= RESTART: D:/C Data 16-02-24/Desktop/Python_assignment_tops/Module 3/Same_value_of_dict_and_Pluse.py
<class 'collections.Counter'>
Counter({'item1': 1150, 'item2': 300})

= RESTART: D:/C Data 16-02-24/Desktop/Python_assignment_tops/Module 3/Same_value_of_dict_and_Pluse.py
Counter({'item1': 1150, 'item2': 300})

= RESTART: D:/C Data 16-02-24/Desktop/Python_assignment_tops/Module 3/Same_value_of_dict_and_Pluse.py
Counter({'item1': 750, 'item2': 300})

= RESTART: D:/C Data 16-02-24/Desktop/Python_assignment_tops/Module 3/create_dictionary_from_string.py
{'w': 1, '3': 1, 'r': 2, 'e': 2, 's': 2, 'o': 1, 'u': 1}

= RESTART: D:/C Data 16-02-24/Desktop/Python_assignment_tops/Module 3/create_dictionary_from_string.py
{'w': 1, '3': 1, 'r': 2, 'e': 2, 's': 2, 'o': 1, 'u': 1}

= RESTART: D:/C Data 16-02-24/Desktop/Python_assignment_tops/Module 3/create_dictionary_from_string.py
Counter({'r': 2, 'e': 2, 's': 2, 'w': 1, '3': 1, 'o': 1, 'u': 1})

= RESTART: D:/C Data 16-02-24/Desktop/Python_assignment_tops/Module 3/create_dictionary_from_string.py
Traceback (most recent call last):
  File "D:/C Data 16-02-24/Desktop/Python_assignment_tops/Module 3/create_dictionary_from_string.py", line 2, in <module>
    print(dit(Counter("w3resourse")))
NameError: name 'dit' is not defined. Did you mean: 'dir'?

= RESTART: D:/C Data 16-02-24/Desktop/Python_assignment_tops/Module 3/create_dictionary_from_string.py
{'w': 1, '3': 1, 'r': 2, 'e': 2, 's': 2, 'o': 1, 'u': 1}

= RESTART: D:/C Data 16-02-24/Desktop/Python_assignment_tops/Module 3/create_dictionary_from_string.py
{'w': 1, '3': 1, 'r': 2, 'e': 2, 's': 2, 'o': 1, 'u': 1}
Traceback (most recent call last):
  File "D:/C Data 16-02-24/Desktop/Python_assignment_tops/Module 3/create_dictionary_from_string.py", line 4, in <module>
    print (dict(collections.Counter('w3resource')))
NameError: name 'collections' is not defined. Did you forget to import 'collections'?

= RESTART: D:/C Data 16-02-24/Desktop/Python_assignment_tops/Module 3/create_dictionary_from_string.py
{'w': 1, '3': 1, 'r': 2, 'e': 2, 's': 2, 'o': 1, 'u': 1}
{'w': 1, '3': 1, 'r': 2, 'e': 2, 's': 1, 'o': 1, 'u': 1, 'c': 1}
{'w': 1, '3': 1, 'r': 2, 'e': 2, 's': 1, 'o': 1, 'u': 1, 'c': 1}

= RESTART: D:/C Data 16-02-24/Desktop/Python_assignment_tops/Module 3/create_dictionary_from_string.py
{'w': 1, '3': 1, 'r': 2, 'e': 2, 's': 2, 'o': 1, 'u': 1}

= RESTART: D:/C Data 16-02-24/Desktop/Python_assignment_tops/Module 3/create_dictionary_from_string.py
Traceback (most recent call last):
  File "D:/C Data 16-02-24/Desktop/Python_assignment_tops/Module 3/create_dictionary_from_string.py", line 1, in <module>
    from collactions import Counter as new
ModuleNotFoundError: No module named 'collactions'

= RESTART: D:/C Data 16-02-24/Desktop/Python_assignment_tops/Module 3/create_dictionary_from_string.py
{'T': 2, 'o': 3, 'p': 1, 's': 2, 'e': 2, 'c': 1, 'h': 1, 'n': 1, 'l': 1, 'g': 1, 'i': 1}

= RESTART: D:/C Data 16-02-24/Desktop/Python_assignment_tops/Module 3/create_dictionary_from_string.py
{'T': 2, 'o': 3, 'p': 1, 's': 2, 'e': 2, 'c': 1, 'h': 1, 'n': 1, 'l': 1, 'g': 1, 'i': 1}
Counter({'o': 3, 't': 2, 's': 2, 'e': 2, 'p': 1, 'c': 1, 'h': 1, 'n': 1, 'l': 1, 'g': 1, 'i': 1})

= RESTART: D:/C Data 16-02-24/Desktop/Python_assignment_tops/Module 3/create_dictionary_from_string.py
Counter({'o': 3, 's': 2, 'e': 2, 'T': 1, 'p': 1, 't': 1, 'c': 1, 'h': 1, 'n': 1, 'l': 1, 'g': 1, 'i': 1})

= RESTART: D:/C Data 16-02-24/Desktop/Python_assignment_tops/Module 3/create_dictionary_from_string.py
{'T': 1, 'o': 3, 'p': 1, 's': 2, 't': 1, 'e': 2, 'c': 1, 'h': 1, 'n': 1, 'l': 1, 'g': 1, 'i': 1}

= RESTART: D:/C Data 16-02-24/Desktop/Python_assignment_tops/Module 3/create_dictionary_from_string.py
{'T': 1, 'o': 3, 'p': 1, 's': 2, 't': 1, 'e': 2, 'c': 1, 'h': 1, 'n': 1, 'l': 1, 'g': 1, 'i': 1}

= RESTART: D:/C Data 16-02-24/Desktop/Python_assignment_tops/Module 3/create_dictionary_from_string.py
<class 'dict'>

= RESTART: D:/C Data 16-02-24/Desktop/Python_assignment_tops/Module 3/create_dictionary_from_string.py
{'T': 1, 'o': 3, 'p': 1, 's': 2, 't': 1, 'e': 2, 'c': 1, 'h': 1, 'n': 1, 'l': 1, 'g': 1, 'i': 1}

= RESTART: D:/C Data 16-02-24/Desktop/Python_assignment_tops/Module 3/create_dictionary_from_string.py
{'T': 1, 'o': 3, 'p': 1, 's': 2, 't': 1, 'e': 2, 'c': 1, 'h': 1, 'n': 1, 'l': 1, 'g': 1, 'i': 1}

= RESTART: D:/C Data 16-02-24/Desktop/Python_assignment_tops/Module 3/create_dictionary_from_string.py
{'T': 1, 'o': 3, 'p': 1, 's': 2, 't': 1, 'e': 2, 'c': 1, 'h': 1, 'n': 1, 'l': 1, 'g': 1, 'i': 1}

= RESTART: D:/C Data 16-02-24/Desktop/Python_assignment_tops/Module 3/create_dictionary_from_string.py
{'T': 1, 'o': 3, 'p': 1, 's': 2, 't': 1, 'e': 2, 'c': 1, 'h': 1, 'n': 1, 'l': 1, 'g': 1, 'i': 1}
Counter({'n': 6, 'm': 5, ' ': 5, 'i': 4, 'o': 3, 'd': 3, 'w': 2, 'u': 1, 'a': 1, 'r': 1, 'h': 1, 'e': 1})

= RESTART: D:/C Data 16-02-24/Desktop/Python_assignment_tops/Module 3/Calculate_The _factorial.py
0
1
2
3
4
5
6
7
8
9
>>> 
= RESTART: D:/C Data 16-02-24/Desktop/Python_assignment_tops/Module 3/Calculate_The _factorial.py
Enter your number : 12
479001600
>>> 
= RESTART: D:/C Data 16-02-24/Desktop/Python_assignment_tops/Module 3/Calculate_The _factorial.py
Enter your number : 5
120
>>> 
= RESTART: D:/C Data 16-02-24/Desktop/Python_assignment_tops/Module 3/Calculate_The _factorial.py
Enter your number : 12
479001600
Enter number : 12
Even
>>> 
= RESTART: D:/C Data 16-02-24/Desktop/Python_assignment_tops/Module 3/Calculate_The _factorial.py
Enter your number : -1
1
>>> 
= RESTART: D:/C Data 16-02-24/Desktop/Python_assignment_tops/Module 3/Calculate_The _factorial.py
Enter your number : 0
1
